Workbook

Sheet Historical Data
B3: Eternal Ltd. Financial Model
B4: (Formerly Zomato Limited) | C4: Circuit Switch: | D4: ON
C5: Operating scenario: | D5: Base Case
C6: Target Price: | D6: 71.85
B9: All figures in ₹ Cr unless otherwise stated
C10: Historical Income Statement
B11: Income Statement(₹ Cr) | C11: FY23A | D11: FY24A | E11: FY25A
B13: [Income Statement]
B14: Income:
B15: Revenue from Operations | C15: 7079 | D15: 12114 | E15: 20243
B16: Other Income | C16: 682 | D16: 847 | E16: 1077
B17: Toatal Income | C17: =SUM(C15:C16) -> 7761 | D17: =SUM(D15:D16) -> 12961 | E17: =SUM(E15:E16) -> 21320
B19: Operating Expenses:
B20: Purchase of Stock-in-Trade | C20: 1438 | D20: 2887 | E20: 5653
B21: Changes in Inventories | C21: -43 | D21: -5 | E21: -88
B22: Employee Benefits Expense | C22: 1465 | D22: 1659 | E22: 2558
B23: Finance Costs | C23: 49 | D23: 72 | E23: 154
B24: Depreciation and Amortization | C24: 437 | D24: 526 | E24: 863
B25: Other Expenses | C25: 5429 | D25: 7531 | E25: 11483
B26: Total Expenses | C26: =SUM(C20:C25) -> 8775 | D26: =SUM(D20:D25) -> 12670 | E26: =SUM(E20:E25) -> 20623
B27: PBT | C27: =C17-C26 -> -1014 | D27: =D17-D26 -> 291 | E27: =E17-E26 -> 697
B28: Tax Expenses | C28: 44 | D28: -60 | E28: 170
B29: Net Income (PAT) | C29: =C27-C28 -> -1058 | D29: =D27-D28 -> 351 | E29: =E27-E28 -> 527
C32: Historical Balance Sheet
B33: Balance Sheet(₹ Cr) | C33: FY23A | D33: FY24A | E33: FY25A
B35: [Balance Sheet]
B36: ASSETS
B37: NON-CURRENT ASSETS
B38: Property, Plant and Equipment | C38: 209 | D38: 287 | E38: 965
B39: Capital Work-in-Progress | C39: 7 | D39: 18 | E39: 51
B40: Right-of-use Asset | C40: 427 | D40: 690 | E40: 1918
B41: Goodwill | C41: 4717 | D41: 4717 | E41: 5737
B42: Other Intangible Assets | C42: 991 | D42: 754 | E42: 912
B43: Investments (Non-current) | C43: 2280 | D43: 10365 | E43: 10920
B44: Other Financial Assets (Non-current) | C44: 1894 | D44: 747 | E44: 2744
B45: Tax Assets (Net) | C45: 116 | D45: 221 | E45: 129
B46: Other Non-current Assets | C46: 127 | D46: 99 | E46: 546
B47: TOTAL NON-CURRENT ASSETS | C47: =SUM(C38:C46) -> 10768 | D47: =SUM(D38:D46) -> 17898 | E47: =SUM(E38:E46) -> 23922
B49: CURRENT ASSETS
B50: Inventories | C50: 83 | D50: 88 | E50: 176
...

Sheet Assumptions
B2: Assumption | C2: FY26E | D2: FY27E | E2: FY28E | F2: FY29E | G2: FY30E
B3: Revenue Growth | C3: 0.3 | D3: 0.25 | E3: 0.2 | F3: 0.15 | G3: 0.12
B4: Other Income Growth | C4: 0.1 | D4: 0.1 | E4: 0.1 | F4: 0.1 | G4: 0.1
B5: COGS % Revenue | C5: 0.28 | D5: 0.28 | E5: 0.28 | F5: 0.28 | G5: 0.28
B6: Employee Cost % Revenue | C6: 0.125 | D6: 0.12 | E6: 0.115 | F6: 0.11 | G6: 0.105
B7: Other Expense % Revenue | C7: 0.55 | D7: 0.53 | E7: 0.51 | F7: 0.49 | G7: 0.48
B8: D&A % Revenue | C8: 0.04 | D8: 0.04 | E8: 0.04 | F8: 0.04 | G8: 0.04
B9: Finance Cost (₹ Cr) | C9: 154 | D9: 154 | E9: 154 | F9: 154 | G9: 154
B10: Tax Rate | C10: 0.25 | D10: 0.25 | E10: 0.25 | F10: 0.25 | G10: 0.25
B11: Receivable Days | C11: 35 | D11: 34 | E11: 33 | F11: 32 | G11: 31
B12: Payable Days | C12: 95 | D12: 92 | E12: 90 | F12: 88 | G12: 85
A13: Advertising & marketing is approximately 25-30% of Other Expenses based on management commentary. Not modeled separately for simplicity." | B13: Capex % Revenue | C13: 0.06 | D13: 0.06 | E13: 0.05 | F13: 0.05 | G13: 0.04
B14: Inventory days | C14: 11 | D14: 11 | E14: 11 | F14: 11 | G14: 11
B15: Share based compensation | C15: 798 | D15: 850 | E15: 900 | F15: 950 | G15: 1000
B16: Other current liabilities % revenue | C16: ='Financial Model'!C57/'Financial Model'!C4 -> 0.022328706 | D16: ='Financial Model'!D57/'Financial Model'!D4 -> 0.022328706 | E16: ='Financial Model'!E57/'Financial Model'!E4 -> 0.022328706 | F16: ='Financial Model'!F57/'Financial Model'!F4 -> 0.022328706 | G16: ='Financial Model'!G57/'Financial Model'!G4 -> 0.022328706
B19: Lease Schedule
B20: (₹ Cr) | C20: FY26 | D20: FY27 | E20: FY28 | F20: FY29 | G20: FY30
B21: Opening ROU | C21: 1918 | D21: 2078 | E21: 2253 | F21: =E24 -> 2403 | G21: =F24 -> 2554.6667
B22: New Leases (40% of CapEx) | C22: 240 | D22: 300 | E22: 250 | F22: 273.33333 | G22: 273.33333
B23: Lease Depreciation (included in D&A) | C23: -80 | D23: -125 | E23: -100 | F23: -121.66667 | G23: -121.66667
B24: Closing ROU | C24: =SUM(C21:C23) -> 2078 | D24: =SUM(D21:D23) -> 2253 | E24: =SUM(E21:E23) -> 2403 | F24: =SUM(F21:F23) -> 2554.6667 | G24: =SUM(G21:G23) -> 2706.3333

Sheet Financial Model
B2: All figures in ₹ Cr unless otherwise stated
B3: Forecast Income Statement (₹ Cr) | C3: FY25E | D3: FY26E | E3: FY27E | F3: FY28E | G3: FY29E | H3: FY30E
B4: Revenue | C4: ='Historical Data'!E15 -> 20243 | D4: =C4*(1+Assumptions!C3) -> 26315.9 | E4: =D4*(1+Assumptions!D3) -> 32894.875 | F4: =E4*(1+Assumptions!E3) -> 39473.85 | G4: =F4*(1+Assumptions!F3) -> 45394.927 | H4: =G4*(1+Assumptions!G3) -> 50842.319
B5: Other Income | C5: ='Historical Data'!E16 -> 1077 | D5: =C5*(1+Assumptions!C4) -> 1184.7 | E5: =D5*(1+Assumptions!D4) -> 1303.17 | F5: =E5*(1+Assumptions!E4) -> 1433.487 | G5: =F5*(1+Assumptions!F4) -> 1576.8357 | H5: =G5*(1+Assumptions!G4) -> 1734.5193
B6: Total Income | C6: =SUM(C4:C5) -> 21320 | D6: =SUM(D4:D5) -> 27500.6 | E6: =SUM(E4:E5) -> 34198.045 | F6: =SUM(F4:F5) -> 40907.337 | G6: =SUM(G4:G5) -> 46971.763 | H6: =SUM(H4:H5) -> 52576.838
B7: COGS | D7: =D4*Assumptions!C5 -> 7368.452 | E7: =E4*Assumptions!D5 -> 9210.565 | F7: =F4*Assumptions!E5 -> 11052.678 | G7: =G4*Assumptions!F5 -> 12710.58 | H7: =H4*Assumptions!G5 -> 14235.849
B8: Employee Benefits | D8: =D4*Assumptions!C6 -> 3289.4875 | E8: =E4*Assumptions!D6 -> 3947.385 | F8: =F4*Assumptions!E6 -> 4539.4928 | G8: =G4*Assumptions!F6 -> 4993.442 | H8: =H4*Assumptions!G6 -> 5338.4435
B9: Depreciation & Amortization | D9: =D4*Assumptions!C8 -> 1052.636 | E9: =E4*Assumptions!D8 -> 1315.795 | F9: =F4*Assumptions!E8 -> 1578.954 | G9: =G4*Assumptions!F8 -> 1815.7971 | H9: =H4*Assumptions!G8 -> 2033.6928
B10: Finance Costs | D10: =Assumptions!C9 -> 154 | E10: =Assumptions!D9 -> 154 | F10: =Assumptions!E9 -> 154 | G10: =Assumptions!F9 -> 154 | H10: =Assumptions!G9 -> 154
B11: Other Expenses | D11: =D4*Assumptions!C7 -> 14473.745 | E11: =E4*Assumptions!D7 -> 17434.284 | F11: =F4*Assumptions!E7 -> 20131.663 | G11: =G4*Assumptions!F7 -> 22243.514 | H11: =H4*Assumptions!G7 -> 24404.313
B12: Total Expenses | D12: =SUM(D7:D11) -> 26338.321 | E12: =SUM(E7:E11) -> 32062.029 | F12: =SUM(F7:F11) -> 37456.788 | G12: =SUM(G7:G11) -> 41917.333 | H12: =SUM(H7:H11) -> 46166.299
B13: PBT | D13: =D6-D12 -> 1162.2795 | E13: =E6-E12 -> 2136.0162 | F13: =F6-F12 -> 3450.5488 | G13: =G6-G12 -> 5054.4299 | H13: =H6-H12 -> 6410.5396
B14: Tax | D14: =IF(D13>0,D13*Assumptions!C10,0) -> 290.56988 | E14: =IF(E13>0,E13*Assumptions!D10,0) -> 534.00406 | F14: =IF(F13>0,F13*Assumptions!E10,0) -> 862.63719 | G14: =IF(G13>0,G13*Assumptions!F10,0) -> 1263.6075 | H14: =IF(H13>0,H13*Assumptions!G10,0) -> 1602.6349
B15: Net Income (PAT) | D15: =D13-D14 -> 871.70963 | E15: =E13-E14 -> 1602.0122 | F15: =F13-F14 -> 2587.9116 | G15: =G13-G14 -> 3790.8224 | H15: =H13-H14 -> 4807.9047
B18: Forecast Balance Sheet (₹ Cr) | C18: FY25E | D18: FY26E | E18: FY27E | F18: FY28E | G18: FY29E | H18: FY30E
B20: ASSETS:
B21: Trade Receivables | C21: ='Historical Data'!E52 -> 1946 | D21: =D4*Assumptions!C11/365 -> 2523.4425 | E21: =E4*Assumptions!D11/365 -> 3064.1801 | F21: =F4*Assumptions!E11/365 -> 3568.8686 | G21: =G4*Assumptions!F11/365 -> 3979.8293 | H21: =H4*Assumptions!G11/365 -> 4318.1147
B22: Inventory | C22: ='Historical Data'!E50 -> 176 | D22: =D7*Assumptions!C14/365 -> 222.06294 | E22: =E7*Assumptions!D14/365 -> 277.57867 | F22: =F7*Assumptions!E14/365 -> 333.09441 | G22: =G7*Assumptions!F14/365 -> 383.05857 | H22: =H7*Assumptions!G14/365 -> 429.02559
B23: Current Investments | C23: ='Historical Data'!E51 -> 2272 | D23: 2272 | E23: 2272 | F23: 2272 | G23: 2272 | H23: 2272
B24: Bank balance other than cash | C24: ='Historical Data'!E54 -> 2948 | D24: 2948 | E24: 2948 | F24: 2948 | G24: 2948 | H24: 2948
B25: Other Financial Assets | C25: ='Historical Data'!E56 -> 2769 | D25: 2769 | E25: 2769 | F25: 2769 | G25: 2769 | H25: 2769
B26: Other Current Assets | C26: 924 | D26: =D4*(C26/C4) -> 1201.2 | E26: =E4*(D26/D4) -> 1501.5 | F26: =F4*(E26/E4) -> 1801.8 | G26: =G4*(F26/F4) -> 2072.07 | H26: =H4*(G26/G4) -> 2320.7184
B27: Cash & Cash Equivalents | C27: ='Historical Data'!E53 -> 666 | D27: =D93 -> 1346.1025 | E27: =E93 -> 2669.3146 | F27: =F93 -> 5352.6342 | G27: =G93 -> 9258.0066 | H27: =H93 -> 14683.706
B28: Total Current Assets | C28: =SUM(C21:C27) -> 11701 | D28: =SUM(D21:D27) -> 13281.808 | E28: =SUM(E21:E27) -> 15501.573 | F28: =SUM(F21:F27) -> 19045.397 | G28: =SUM(G21:G27) -> 23681.964 | H28: =SUM(H21:H27) -> 29740.565
B29: PPE | C29: ='Historical Data'!E38 -> 965 | D29: =C29-D80-(D69+Assumptions!C23) -> 1571.318 | E29: =D29-E80-(E69+Assumptions!D23) -> 2354.2155 | F29: =E29-F80-(F69+Assumptions!E23) -> 2848.954 | G29: =F29-G80-(G69+Assumptions!F23) -> 3424.5699 | H29: =G29-H80-(H69+Assumptions!G23) -> 3546.2366
B30: CWIP | C30: ='Historical Data'!E39 -> 51 | D30: 51 | E30: 51 | F30: 51 | G30: 51 | H30: 51
B31: ROU Asset | C31: ='Historical Data'!E40 -> 1918 | D31: =Assumptions!C24 -> 2078 | E31: =Assumptions!D24 -> 2253 | F31: =Assumptions!E24 -> 2403 | G31: =Assumptions!F24 -> 2554.6667 | H31: =Assumptions!G24 -> 2706.3333
B32: Goodwill | C32: ='Historical Data'!E41 -> 5737 | D32: 5737 | E32: 5737 | F32: 5737 | G32: 5737 | H32: 5737
B33: Intangibles | C33: ='Historical Data'!E42 -> 912 | D33: 912 | E33: 912 | F33: 912 | G33: 912 | H33: 912
B34: Investments | C34: ='Historical Data'!E43 -> 10920 | D34: 10920 | E34: 10920 | F34: 10920 | G34: 10920 | H34: 10920
B35: Other Financial Assets | C35: ='Historical Data'!E44 -> 2744 | D35: 2744 | E35: 2744 | F35: 2744 | G35: 2744 | H35: 2744
B36: Tax Assets | C36: ='Historical Data'!E45 -> 129 | D36: 129 | E36: 129 | F36: 129 | G36: 129 | H36: 129
B37: Other Non-Current Assets | C37: ='Historical Data'!E46 -> 546 | D37: 546 | E37: 546 | F37: 546 | G37: 546 | H37: 546
B38: Total Non-Current Assets | C38: =SUM(C29:C37) -> 23922 | D38: =SUM(D29:D37) -> 24688.318 | E38: =SUM(E29:E37) -> 25646.215 | F38: =SUM(F29:F37) -> 26290.954 | G38: =SUM(G29:G37) -> 27018.237 | H38: =SUM(H29:H37) -> 27291.57
B40: TOTAL ASSETS | C40: =C28+C38 -> 35623 | D40: =D28+D38 -> 37970.126 | E40: =E28+E38 -> 41147.789 | F40: =F28+F38 -> 45336.351 | G40: =G28+G38 -> 50700.201 | H40: =H28+H38 -> 57032.135
B43: LIABILITIES & EQUITY:
B44: Equity Share Capital | C44: ='Historical Data'!E63 -> 907 | D44: 907 | E44: 907 | F44: 907 | G44: 907 | H44: 907
B45: Other Equity | C45: ='Historical Data'!E64 -> 29410 | D45: =C45+D15+Assumptions!C15 -> 31079.71 | E45: =D45+E15+Assumptions!D15 -> 33531.722 | F45: =E45+F15+Assumptions!E15 -> 37019.633 | G45: =F45+G15+Assumptions!F15 -> 41760.456 | H45: =G45+H15+Assumptions!G15 -> 47568.36
B46: TOTAL EQUITY | C46: =SUM(C44:C45) -> 30317 | D46: =SUM(D44:D45) -> 31986.71 | E46: =SUM(E44:E45) -> 34438.722 | F46: =SUM(F44:F45) -> 37926.633 | G46: =SUM(G44:G45) -> 42667.456 | H46: =SUM(H44:H45) -> 48475.36
B47: NCI | C47: ='Historical Data'!E65 -> -7 | D47: -7 | E47: -7 | F47: -7 | G47: -7 | H47: -7
...

Sheet Operational Drivers and Metric
B2: Historical Margin Analysis:
B3: Metric | C3: FY23 | D3: FY24 | E3: FY25
B4: Revenue Growth % | D4: =('Historical Data'!D15-'Historical Data'!C15)/'Historical Data'!C15 -> 0.71125865 | E4: =('Historical Data'!E15-'Historical Data'!D15)/'Historical Data'!D15 -> 0.67104177
B5: Gross Margin % | C5: 0 | D5: 0 | E5: 0
B6: EBITDA Margin % | C6: =(('Historical Data'!C17-'Historical Data'!C20-'Historical Data'!C21-'Historical Data'!C22-'Historical Data'!C25)/'Historical Data'!C15) -> -0.074586806 | D6: =(('Historical Data'!D17-'Historical Data'!D20-'Historical Data'!D21-'Historical Data'!D22-'Historical Data'!D25)/'Historical Data'!D15) -> 0.073386165 | E6: =(('Historical Data'!E17-'Historical Data'!E20-'Historical Data'!E21-'Historical Data'!E22-'Historical Data'!E25)/'Historical Data'!E15) -> 0.084671244
B7: EBIT Margin % | C7: =C6-('Historical Data'!C24/'Historical Data'!C15) -> -0.13631869 | D7: =D6-('Historical Data'!D24/'Historical Data'!D15) -> 0.029965329 | E7: =E6-('Historical Data'!E24/'Historical Data'!E15) -> 0.042039223
B8: Net Margin % | C8: ='Historical Data'!C29/'Historical Data'!C15 -> -0.14945614 | D8: ='Historical Data'!D29/'Historical Data'!D15 -> 0.02897474 | E8: ='Historical Data'!E29/'Historical Data'!E15 -> 0.026033691
B9: Employee Cost % Revenue | C9: ='Historical Data'!C22/'Historical Data'!C15 -> 0.20695013 | D9: ='Historical Data'!D22/'Historical Data'!D15 -> 0.13694898 | E9: ='Historical Data'!E22/'Historical Data'!E15 -> 0.12636467
B10: Other Expenses % Revenue | C10: ='Historical Data'!C25/'Historical Data'!C15 -> 0.76691623 | D10: ='Historical Data'!D25/'Historical Data'!D15 -> 0.6216774 | E10: ='Historical Data'!E25/'Historical Data'!E15 -> 0.56725782
B11: D&A % Revenue | C11: ='Historical Data'!C24/'Historical Data'!C15 -> 0.061731883 | D11: ='Historical Data'!D24/'Historical Data'!D15 -> 0.043420835 | E11: ='Historical Data'!E24/'Historical Data'!E15 -> 0.042632021
B12: Effective Tax Rate | C12: ='Historical Data'!C28/'Historical Data'!C27 -> -0.043392505 | D12: ='Historical Data'!D28/'Historical Data'!D27 -> -0.20618557 | E12: ='Historical Data'!E28/'Historical Data'!E27 -> 0.24390244
B14: Working Capital Metrics:
B15: Metric | C15: FY23 | D15: FY24 | E15: FY25 | F15: FY26 | G15: FY27
B16: Receivable Days | C16: ='Historical Data'!C52/'Historical Data'!C15*365 -> 23.563356 | D16: ='Historical Data'!D52/'Historical Data'!D15*365 -> 23.92356 | E16: ='Historical Data'!E52/'Historical Data'!E15*365 -> 35.088179
B17: Payable Days | C17: ='Historical Data'!C79/'Historical Data'!C20*365 -> 172.34701 | D17: ='Historical Data'!D79/'Historical Data'!D20*365 -> 112.01593 | E17: ='Historical Data'!E79/'Historical Data'!E20*365 -> 99.175659
B18: Inventory Days | C18: ='Historical Data'!C50/'Historical Data'!C20*365 -> 21.067455 | D18: ='Historical Data'!D50/'Historical Data'!D20*365 -> 11.125736 | E18: ='Historical Data'!E50/'Historical Data'!E20*365 -> 11.363878
B20: Forecast Assumptions:
B21: Assumption | C21: FY26 | D21: FY27 | E21: FY28
B22: Revenue Growth | C22: =Assumptions!C3 -> 0.3 | D22: =Assumptions!D3 -> 0.25 | E22: =Assumptions!E3 -> 0.2
B23: EBITDA Margin | C23: =1-Assumptions!C5-Assumptions!C6-Assumptions!C7 -> 0.045 | D23: =1-Assumptions!D5-Assumptions!D6-Assumptions!D7 -> 0.07 | E23: =1-Assumptions!E5-Assumptions!E6-Assumptions!E7 -> 0.095
B24: Tax Rate | C24: =Assumptions!C10 -> 0.25 | D24: =Assumptions!D10 -> 0.25 | E24: =Assumptions!E10 -> 0.25
B25: Receivable Days | C25: =Assumptions!C11 -> 35 | D25: =Assumptions!D11 -> 34 | E25: =Assumptions!E11 -> 33
B26: Payable Days | C26: =Assumptions!C12 -> 95 | D26: =Assumptions!D12 -> 92 | E26: =Assumptions!E12 -> 90
B27: Capex % Revenue | C27: =Assumptions!C13 -> 0.06 | D27: =Assumptions!D13 -> 0.06 | E27: =Assumptions!E13 -> 0.05

Sheet Valuation Output
B2: OPERATING METRICS | C2: FY26 | D2: FY27 | E2: FY28
B3: Revenue | C3: ='Financial Model'!D4 -> 26315.9 | D3: ='Financial Model'!E4 -> 32894.875 | E3: ='Financial Model'!F4 -> 39473.85
B4: Revenue Growth % | C4: ='Financial Model'!D4/'Financial Model'!C4-1 -> 0.3 | D4: ='Financial Model'!E4/'Financial Model'!D4-1 -> 0.25 | E4: ='Financial Model'!F4/'Financial Model'!E4-1 -> 0.2
B5: EBITDA | C5: ='Financial Model'!D13+'Financial Model'!D10+'Financial Model'!D9 -> 2368.9155 | D5: ='Financial Model'!E13+'Financial Model'!E10+'Financial Model'!E9 -> 3605.8112 | E5: ='Financial Model'!F13+'Financial Model'!F10+'Financial Model'!F9 -> 5183.5028
B6: EBITDA Margin% | C6: =C5/'Financial Model'!D4 -> 0.090018411 | D6: =D5/'Financial Model'!E4 -> 0.1096162 | E6: =E5/'Financial Model'!F4 -> 0.13131485
B7: PAT | C7: ='Financial Model'!D15 -> 871.70963 | D7: ='Financial Model'!E15 -> 1602.0122 | E7: ='Financial Model'!F15 -> 2587.9116
B8: PAT Margin % | C8: =C7/'Financial Model'!D4 -> 0.033124827 | D8: =D7/'Financial Model'!E4 -> 0.048700966 | E8: =E7/'Financial Model'!F4 -> 0.065560151
B10: BALANCE SHEET METRICS | C10: FY26 | D10: FY27 | E10: FY28
B11: Net Working Capital | C11: ='Financial Model'!D28-'Financial Model'!D60 -> 9388.3916 | D11: ='Financial Model'!E28-'Financial Model'!E60 -> 11022.506 | E11: ='Financial Model'!F28-'Financial Model'!F60 -> 13985.679
B12: ROIC(later) | C12: 0 | D12: 0 | E12: 0
B13: Net Cash | C13: =('Financial Model'!D27+'Financial Model'!D24+'Financial Model'!D23)-('Financial Model'!D49+'Financial Model'!D55) -> 4361.1025 | D13: =('Financial Model'!E27+'Financial Model'!E24+'Financial Model'!E23)-('Financial Model'!E49+'Financial Model'!E55) -> 5509.3146 | E13: =('Financial Model'!F27+'Financial Model'!F24+'Financial Model'!F23)-('Financial Model'!F49+'Financial Model'!F55) -> 8042.6342
B15: CASH FLOW METRICS | C15: FY26 | D15: FY27 | E15: FY28
B16: CFO | C16: ='Financial Model'!D77 -> 1308.3565 | D16: ='Financial Model'!E77 -> 2272.7346 | E16: ='Financial Model'!F77 -> 3477.5251
B17: FCF | C17: ='Financial Model'!D77+'Financial Model'!D80 -> -270.5975 | D17: ='Financial Model'!E77+'Financial Model'!E80 -> 299.04208 | E17: ='Financial Model'!F77+'Financial Model'!F80 -> 1503.8326
B19: DCF ASSUMPTION | C19: Value
B20: WACC | C20: 0.11
B21: Terminal Growth Rate | C21: 0.04
B22: Terminal Year | C22: FY30
B23: Shares Outstanding | C23: ='Historical Data'!E63 -> 907
B25: FCFF Schedule | C25: FY25 | D25: FY26 | E25: FY27 | F25: FY28 | G25: FY29 | H25: FY30
B26: EBIT | D26: ='Financial Model'!D13+'Financial Model'!D10 -> 1316.2795 | E26: ='Financial Model'!E13+'Financial Model'!E10 -> 2290.0162 | F26: ='Financial Model'!F13+'Financial Model'!F10 -> 3604.5488 | G26: ='Financial Model'!G13+'Financial Model'!G10 -> 5208.4299 | H26: ='Financial Model'!H13+'Financial Model'!H10 -> 6564.5396
B27: Tax | D27: =D26*Assumptions!C10 -> 329.06988 | E27: =E26*Assumptions!D10 -> 572.50406 | F27: =F26*Assumptions!E10 -> 901.13719 | G27: =G26*Assumptions!F10 -> 1302.1075 | H27: =H26*Assumptions!G10 -> 1641.1349
B28: NOPAT | D28: =D26-D27 -> 987.20963 | E28: =E26-E27 -> 1717.5122 | F28: =F26-F27 -> 2703.4116 | G28: =G26-G27 -> 3906.3224 | H28: =H26-H27 -> 4923.4047
B29: D&A | D29: ='Financial Model'!D9 -> 1052.636 | E29: ='Financial Model'!E9 -> 1315.795 | F29: ='Financial Model'!F9 -> 1578.954 | G29: ='Financial Model'!G9 -> 1815.7971 | H29: ='Financial Model'!H9 -> 2033.6928
B30: Capex | D30: ='Financial Model'!D80 -> -1578.954 | E30: ='Financial Model'!E80 -> -1973.6925 | F30: ='Financial Model'!F80 -> -1973.6925 | G30: ='Financial Model'!G80 -> -2269.7464 | H30: ='Financial Model'!H80 -> -2033.6928
B31: Working Capital | D31: ='Financial Model'!D21+'Financial Model'!D22+'Financial Model'!D26-'Financial Model'!D58-'Financial Model'!D57 -> 1441.2891 | E31: ='Financial Model'!E21+'Financial Model'!E22+'Financial Model'!E26-'Financial Model'!E58-'Financial Model'!E57 -> 1787.1917 | F31: ='Financial Model'!F21+'Financial Model'!F22+'Financial Model'!F26-'Financial Model'!F58-'Financial Model'!F57 -> 2097.0452 | G31: ='Financial Model'!G21+'Financial Model'!G22+'Financial Model'!G26-'Financial Model'!G58-'Financial Model'!G57 -> 2356.8793 | H31: ='Financial Model'!H21+'Financial Model'!H22+'Financial Model'!H26-'Financial Model'!H58-'Financial Model'!H57 -> 2617.4178
B32: Change in working capital | C32: ='Financial Model'!C21+'Financial Model'!C22+'Financial Model'!C26-'Financial Model'!C58-'Financial Model'!C57 -> 1058 | D32: =D31-C32 -> 383.28913 | E32: =E31-D31 -> 345.90261 | F32: =F31-E31 -> 309.85343 | G32: =G31-F31 -> 259.83412 | H32: =H31-G31 -> 260.53847
B33: FCFF | D33: =D28+D29+D30-D32 -> 77.602496 | E33: =E28+E29+E30-E32 -> 713.71208 | F33: =F28+F29+F30-F32 -> 1998.8196 | G33: =G28+G29+G30-G32 -> 3192.539 | H33: =H28+H29+H30-H32 -> 4662.8662
B34: Discount Factor | D34: =1/(1+C20)^1 -> 0.9009009 | E34: =1/(1+C20)^2 -> 0.81162243 | F34: =1/(1+C20)^3 -> 0.73119138 | G34: =1/(1+C20)^4 -> 0.65873097 | H34: =1/(1+C20)^5 -> 0.59345133
B35: PV of FCFF | D35: =D33*D34 -> 69.912159 | E35: =E33*E34 -> 579.26473 | F35: =F33*F34 -> 1461.5197 | G35: =G33*G34 -> 2103.0243 | H35: =H33*H34 -> 2767.1841
B36: Terminal Value | H36: =H33*(1+C21)/(C20-C21) -> 69276.869
B37: PV of Terminal Value | H37: =H36*H34 -> 41112.45
B39: VALUATION SUMMARY | D39: Value
B40: Enterprise Value | D40: =SUM(D35:H35)+H37 -> 48093.355
B41: Cash | D41: ='Financial Model'!H27+'Financial Model'!H23+'Financial Model'!H24 -> 19903.706
B42: Debt | D42: ='Financial Model'!H55+'Financial Model'!H49 -> 2833.3333
B43: Equity Value | D43: =D40+D41-D42 -> 65163.728
B44: Shares Outstanding | D44: =C23 -> 907
B45: Intrinsic Value Per Share | D45: =D43/D44 -> 71.845345
B47: SENSITIVITY ANALYSIS
...
